2025-03-21 16:07:09,386 - FlaskWebProject - ERROR - Exception on /login [POST]
Traceback (most recent call last):
  File "C:\ProgramData\Miniconda3\lib\site-packages\sqlalchemy\engine\base.py", line 146, in __init__
    self._dbapi_connection = engine.raw_connection()
  File "C:\ProgramData\Miniconda3\lib\site-packages\sqlalchemy\engine\base.py", line 3298, in raw_connection
    return self.pool.connect()
  File "C:\ProgramData\Miniconda3\lib\site-packages\sqlalchemy\pool\base.py", line 449, in connect
    return _ConnectionFairy._checkout(self)
  File "C:\ProgramData\Miniconda3\lib\site-packages\sqlalchemy\pool\base.py", line 1263, in _checkout
    fairy = _ConnectionRecord.checkout(pool)
  File "C:\ProgramData\Miniconda3\lib\site-packages\sqlalchemy\pool\base.py", line 712, in checkout
    rec = pool._do_get()
  File "C:\ProgramData\Miniconda3\lib\site-packages\sqlalchemy\pool\impl.py", line 180, in _do_get
    self._dec_overflow()
  File "C:\ProgramData\Miniconda3\lib\site-packages\sqlalchemy\util\langhelpers.py", line 146, in __exit__
    raise exc_value.with_traceback(exc_tb)
  File "C:\ProgramData\Miniconda3\lib\site-packages\sqlalchemy\pool\impl.py", line 177, in _do_get
    return self._create_connection()
  File "C:\ProgramData\Miniconda3\lib\site-packages\sqlalchemy\pool\base.py", line 390, in _create_connection
    return _ConnectionRecord(self)
  File "C:\ProgramData\Miniconda3\lib\site-packages\sqlalchemy\pool\base.py", line 674, in __init__
    self.__connect()
  File "C:\ProgramData\Miniconda3\lib\site-packages\sqlalchemy\pool\base.py", line 901, in __connect
    pool.logger.debug("Error on connect(): %s", e)
  File "C:\ProgramData\Miniconda3\lib\site-packages\sqlalchemy\util\langhelpers.py", line 146, in __exit__
    raise exc_value.with_traceback(exc_tb)
  File "C:\ProgramData\Miniconda3\lib\site-packages\sqlalchemy\pool\base.py", line 896, in __connect
    self.dbapi_connection = connection = pool._invoke_creator(self)
  File "C:\ProgramData\Miniconda3\lib\site-packages\sqlalchemy\engine\create.py", line 646, in connect
    return dialect.connect(*cargs, **cparams)
  File "C:\ProgramData\Miniconda3\lib\site-packages\sqlalchemy\engine\default.py", line 622, in connect
    return self.loaded_dbapi.connect(*cargs, **cparams)
pyodbc.OperationalError: ('08001', '[08001] [Microsoft][ODBC Driver 17 for SQL Server]TCP Provider: No such host is known.\r\n (11001) (SQLDriverConnect); [08001] [Microsoft][ODBC Driver 17 for SQL Server]Login timeout expired (0); [08001] [Microsoft][ODBC Driver 17 for SQL Server]A network-related or instance-specific error has occurred while establishing a connection to SQL Server. Server is not found or not accessible. Check if instance name is correct and if SQL Server is configured to allow remote connections. For more information see SQL Server Books Online. (11001)')

The above exception was the direct cause of the following exception:

Traceback (most recent call last):
  File "C:\ProgramData\Miniconda3\lib\site-packages\flask\app.py", line 1511, in wsgi_app
    response = self.full_dispatch_request()
  File "C:\ProgramData\Miniconda3\lib\site-packages\flask\app.py", line 919, in full_dispatch_request
    rv = self.handle_user_exception(e)
  File "C:\ProgramData\Miniconda3\lib\site-packages\flask\app.py", line 917, in full_dispatch_request
    rv = self.dispatch_request()
  File "C:\ProgramData\Miniconda3\lib\site-packages\flask\app.py", line 902, in dispatch_request
    return self.ensure_sync(self.view_functions[rule.endpoint])(**view_args)  # type: ignore[no-any-return]
  File "C:\Users\udtg\OneDrive - Chevron\My Documents\GitHub\Udacity-WebApp_of_Tan\FlaskWebProject\views.py", line 67, in login
    user = User.query.filter_by(username=form.username.data).first()
  File "C:\ProgramData\Miniconda3\lib\site-packages\sqlalchemy\orm\query.py", line 2754, in first
    return self.limit(1)._iter().first()  # type: ignore
  File "C:\ProgramData\Miniconda3\lib\site-packages\sqlalchemy\orm\query.py", line 2853, in _iter
    result: Union[ScalarResult[_T], Result[_T]] = self.session.execute(
  File "C:\ProgramData\Miniconda3\lib\site-packages\sqlalchemy\orm\session.py", line 2365, in execute
    return self._execute_internal(
  File "C:\ProgramData\Miniconda3\lib\site-packages\sqlalchemy\orm\session.py", line 2241, in _execute_internal
    conn = self._connection_for_bind(bind)
  File "C:\ProgramData\Miniconda3\lib\site-packages\sqlalchemy\orm\session.py", line 2110, in _connection_for_bind
    return trans._connection_for_bind(engine, execution_options)
  File "<string>", line 2, in _connection_for_bind
  File "C:\ProgramData\Miniconda3\lib\site-packages\sqlalchemy\orm\state_changes.py", line 139, in _go
    ret_value = fn(self, *arg, **kw)
  File "C:\ProgramData\Miniconda3\lib\site-packages\sqlalchemy\orm\session.py", line 1189, in _connection_for_bind
    conn = bind.connect()
  File "C:\ProgramData\Miniconda3\lib\site-packages\sqlalchemy\engine\base.py", line 3274, in connect
    return self._connection_cls(self)
  File "C:\ProgramData\Miniconda3\lib\site-packages\sqlalchemy\engine\base.py", line 148, in __init__
    Connection._handle_dbapi_exception_noconnection(
  File "C:\ProgramData\Miniconda3\lib\site-packages\sqlalchemy\engine\base.py", line 2439, in _handle_dbapi_exception_noconnection
    raise sqlalchemy_exception.with_traceback(exc_info[2]) from e
  File "C:\ProgramData\Miniconda3\lib\site-packages\sqlalchemy\engine\base.py", line 146, in __init__
    self._dbapi_connection = engine.raw_connection()
  File "C:\ProgramData\Miniconda3\lib\site-packages\sqlalchemy\engine\base.py", line 3298, in raw_connection
    return self.pool.connect()
  File "C:\ProgramData\Miniconda3\lib\site-packages\sqlalchemy\pool\base.py", line 449, in connect
    return _ConnectionFairy._checkout(self)
  File "C:\ProgramData\Miniconda3\lib\site-packages\sqlalchemy\pool\base.py", line 1263, in _checkout
    fairy = _ConnectionRecord.checkout(pool)
  File "C:\ProgramData\Miniconda3\lib\site-packages\sqlalchemy\pool\base.py", line 712, in checkout
    rec = pool._do_get()
  File "C:\ProgramData\Miniconda3\lib\site-packages\sqlalchemy\pool\impl.py", line 180, in _do_get
    self._dec_overflow()
  File "C:\ProgramData\Miniconda3\lib\site-packages\sqlalchemy\util\langhelpers.py", line 146, in __exit__
    raise exc_value.with_traceback(exc_tb)
  File "C:\ProgramData\Miniconda3\lib\site-packages\sqlalchemy\pool\impl.py", line 177, in _do_get
    return self._create_connection()
  File "C:\ProgramData\Miniconda3\lib\site-packages\sqlalchemy\pool\base.py", line 390, in _create_connection
    return _ConnectionRecord(self)
  File "C:\ProgramData\Miniconda3\lib\site-packages\sqlalchemy\pool\base.py", line 674, in __init__
    self.__connect()
  File "C:\ProgramData\Miniconda3\lib\site-packages\sqlalchemy\pool\base.py", line 901, in __connect
    pool.logger.debug("Error on connect(): %s", e)
  File "C:\ProgramData\Miniconda3\lib\site-packages\sqlalchemy\util\langhelpers.py", line 146, in __exit__
    raise exc_value.with_traceback(exc_tb)
  File "C:\ProgramData\Miniconda3\lib\site-packages\sqlalchemy\pool\base.py", line 896, in __connect
    self.dbapi_connection = connection = pool._invoke_creator(self)
  File "C:\ProgramData\Miniconda3\lib\site-packages\sqlalchemy\engine\create.py", line 646, in connect
    return dialect.connect(*cargs, **cparams)
  File "C:\ProgramData\Miniconda3\lib\site-packages\sqlalchemy\engine\default.py", line 622, in connect
    return self.loaded_dbapi.connect(*cargs, **cparams)
sqlalchemy.exc.OperationalError: (pyodbc.OperationalError) ('08001', '[08001] [Microsoft][ODBC Driver 17 for SQL Server]TCP Provider: No such host is known.\r\n (11001) (SQLDriverConnect); [08001] [Microsoft][ODBC Driver 17 for SQL Server]Login timeout expired (0); [08001] [Microsoft][ODBC Driver 17 for SQL Server]A network-related or instance-specific error has occurred while establishing a connection to SQL Server. Server is not found or not accessible. Check if instance name is correct and if SQL Server is configured to allow remote connections. For more information see SQL Server Books Online. (11001)')
(Background on this error at: https://sqlalche.me/e/20/e3q8)
